<mujoco model="pendulum">
  <default>
    <geom rgba=".8 .6 .4 1"/>
  </default>

  <asset>
    <texture type="skybox" builtin="gradient" rgb1="1 1 1" rgb2=".6 .8 1" width="256" height="256"/>
  </asset>

  <worldbody>
    <light pos="0 1 1" dir="0 -1 -1" diffuse="1 1 1"/>
    <body name="capsule_0" pos="0 0 1">
      <joint type="ball" pos="0 0 0.2" />
      <geom type="capsule" size="0.06 0.2" />
      <body name="capsule_1" pos="0 0 -0.4">
        <joint axis="0 1 0" pos="0 0 0.15" />
        <joint axis="1 0 0" pos="0 0 0.15"/>
        <geom type="capsule" size="0.04 0.15"/>
        <site name="end1" pos="0 0 -.15" size="0.01"/>
      </body>
    </body>

    <body name="mass" pos="0.3 0 0.1">
      <joint type="free"/>
      <geom size="0.07 0.1" type="cylinder"/>
      <site name="end2" pos="0 0 0.1" size="0.01"/>
    </body>
  </worldbody>

  <tendon>
    <spatial limited="true" range="0 0.6" width="0.005">
      <site site="end1"/>
      <site site="end2"/>
    </spatial>
  </tendon>
</mujoco>